<<<<<<< HEAD
2024-11-05 22:32:50 - INFO - pika.adapters.utils.connection_workflow: Pika version 1.3.2 connecting to ('::1', 5672, 0, 0)
2024-11-05 22:32:52 - ERROR - pika.adapters.utils.io_services_utils: Socket failed to connect: <socket.socket fd=1376, family=23, type=1, proto=6, laddr=('::', 51158, 0, 0)>; error=10061 (Unknown error)
2024-11-05 22:32:52 - ERROR - pika.adapters.utils.connection_workflow: TCP Connection attempt failed: ConnectionRefusedError(10061, 'Unknown error'); dest=(<AddressFamily.AF_INET6: 23>, <SocketKind.SOCK_STREAM: 1>, 6, '', ('::1', 5672, 0, 0))
2024-11-05 22:32:52 - ERROR - pika.adapters.utils.connection_workflow: AMQPConnector - reporting failure: AMQPConnectorSocketConnectError: ConnectionRefusedError(10061, 'Unknown error')
2024-11-05 22:32:52 - INFO - pika.adapters.utils.connection_workflow: Pika version 1.3.2 connecting to ('127.0.0.1', 5672)
2024-11-05 22:32:54 - ERROR - pika.adapters.utils.io_services_utils: Socket failed to connect: <socket.socket fd=1376, family=2, type=1, proto=6, laddr=('0.0.0.0', 51161)>; error=10061 (Unknown error)
2024-11-05 22:32:54 - ERROR - pika.adapters.utils.connection_workflow: TCP Connection attempt failed: ConnectionRefusedError(10061, 'Unknown error'); dest=(<AddressFamily.AF_INET: 2>, <SocketKind.SOCK_STREAM: 1>, 6, '', ('127.0.0.1', 5672))
2024-11-05 22:32:54 - ERROR - pika.adapters.utils.connection_workflow: AMQPConnector - reporting failure: AMQPConnectorSocketConnectError: ConnectionRefusedError(10061, 'Unknown error')
2024-11-05 22:32:54 - ERROR - pika.adapters.utils.connection_workflow: AMQP connection workflow failed: AMQPConnectionWorkflowFailed: 2 exceptions in all; last exception - AMQPConnectorSocketConnectError: ConnectionRefusedError(10061, 'Unknown error'); first exception - AMQPConnectorSocketConnectError: ConnectionRefusedError(10061, 'Unknown error').
2024-11-05 22:32:54 - ERROR - pika.adapters.utils.connection_workflow: AMQPConnectionWorkflow - reporting failure: AMQPConnectionWorkflowFailed: 2 exceptions in all; last exception - AMQPConnectorSocketConnectError: ConnectionRefusedError(10061, 'Unknown error'); first exception - AMQPConnectorSocketConnectError: ConnectionRefusedError(10061, 'Unknown error')
2024-11-05 22:32:54 - ERROR - pika.adapters.blocking_connection: Connection workflow failed: AMQPConnectionWorkflowFailed: 2 exceptions in all; last exception - AMQPConnectorSocketConnectError: ConnectionRefusedError(10061, 'Unknown error'); first exception - AMQPConnectorSocketConnectError: ConnectionRefusedError(10061, 'Unknown error')
2024-11-05 22:32:54 - ERROR - pika.adapters.blocking_connection: Error in _create_connection().
Traceback (most recent call last):
  File "Z:\conda\envs\pyqt-env\Lib\site-packages\pika\adapters\blocking_connection.py", line 451, in _create_connection
    raise self._reap_last_connection_workflow_error(error)
pika.exceptions.AMQPConnectionError
2024-11-05 22:32:54 - ERROR - client: Failed to connect to RabbitMQ: 
=======
2024-11-05 14:44:38 - INFO - pika.adapters.utils.connection_workflow: Pika version 1.3.2 connecting to ('127.0.0.1', 5672)
2024-11-05 14:44:38 - INFO - pika.adapters.utils.io_services_utils: Socket connected: <socket.socket fd=17, family=AddressFamily.AF_INET, type=SocketKind.SOCK_STREAM, proto=6, laddr=('127.0.0.1', 54496), raddr=('127.0.0.1', 5672)>
2024-11-05 14:44:38 - INFO - pika.adapters.utils.connection_workflow: Streaming transport linked up: (<pika.adapters.utils.io_services_utils._AsyncPlaintextTransport object at 0x76bb7dfea4d0>, _StreamingProtocolShim: <SelectConnection PROTOCOL transport=<pika.adapters.utils.io_services_utils._AsyncPlaintextTransport object at 0x76bb7dfea4d0> params=<ConnectionParameters host=localhost port=5672 virtual_host=/ ssl=False>>).
2024-11-05 14:44:38 - INFO - pika.adapters.utils.connection_workflow: AMQPConnector - reporting success: <SelectConnection OPEN transport=<pika.adapters.utils.io_services_utils._AsyncPlaintextTransport object at 0x76bb7dfea4d0> params=<ConnectionParameters host=localhost port=5672 virtual_host=/ ssl=False>>
2024-11-05 14:44:38 - INFO - pika.adapters.utils.connection_workflow: AMQPConnectionWorkflow - reporting success: <SelectConnection OPEN transport=<pika.adapters.utils.io_services_utils._AsyncPlaintextTransport object at 0x76bb7dfea4d0> params=<ConnectionParameters host=localhost port=5672 virtual_host=/ ssl=False>>
2024-11-05 14:44:38 - INFO - pika.adapters.blocking_connection: Connection workflow succeeded: <SelectConnection OPEN transport=<pika.adapters.utils.io_services_utils._AsyncPlaintextTransport object at 0x76bb7dfea4d0> params=<ConnectionParameters host=localhost port=5672 virtual_host=/ ssl=False>>
2024-11-05 14:44:38 - INFO - pika.adapters.blocking_connection: Created channel=1
2024-11-05 14:44:38 - INFO - client: Connected to RabbitMQ and listening on queue: amq.gen-HJXA4qY8jtlNRCfWck7AdQ
2024-11-05 14:44:38 - INFO - client: Sent heartbeat message 'PING' to server.
2024-11-05 14:44:38 - INFO - client: Received response: PONG for request ID: cb738383-d9b3-428f-9b63-049f9e000dca
2024-11-05 14:44:38 - INFO - client: Received heartbeat response PONG from server.
2024-11-05 14:44:48 - INFO - client: Sent heartbeat message 'PING' to server.
2024-11-05 14:44:51 - INFO - client: Sent request: 23 with delay: 0.0 sec
2024-11-05 14:44:58 - INFO - client: Sent heartbeat message 'PING' to server.
2024-11-05 14:44:58 - WARNING - client: Server heartbeat timed out. Server is considered unavailable.
2024-11-05 14:45:02 - INFO - client: Received response: PONG for request ID: a93929d3-b14f-41a1-86dd-6bb0e036f282
2024-11-05 14:45:02 - INFO - client: Received heartbeat response PONG from server.
2024-11-05 14:45:02 - INFO - client: Received response: 46 for request ID: dce9a040-e836-4215-a4a6-d5e7b8222b6f
2024-11-05 14:45:02 - INFO - client: Received response: PONG for request ID: 13a3e593-47a9-4fca-b388-57f47eda6b74
2024-11-05 14:45:02 - INFO - client: Received heartbeat response PONG from server.
2024-11-05 14:45:08 - INFO - client: Sent heartbeat message 'PING' to server.
2024-11-05 14:45:08 - INFO - client: Received response: PONG for request ID: fea58cc5-7e68-4e75-b4f9-1d850a8e1de6
2024-11-05 14:45:08 - INFO - client: Received heartbeat response PONG from server.
2024-11-05 14:45:11 - INFO - pika.adapters.blocking_connection: Closing connection (200): Normal shutdown
2024-11-05 14:45:11 - INFO - pika.channel: Closing channel (200): 'Normal shutdown' on <Channel number=1 OPEN conn=<SelectConnection OPEN transport=<pika.adapters.utils.io_services_utils._AsyncPlaintextTransport object at 0x76bb7dfea4d0> params=<ConnectionParameters host=localhost port=5672 virtual_host=/ ssl=False>>>
2024-11-05 14:45:11 - INFO - pika.channel: Received <Channel.CloseOk> on <Channel number=1 CLOSING conn=<SelectConnection OPEN transport=<pika.adapters.utils.io_services_utils._AsyncPlaintextTransport object at 0x76bb7dfea4d0> params=<ConnectionParameters host=localhost port=5672 virtual_host=/ ssl=False>>>
2024-11-05 14:45:11 - CRITICAL - pika.connection: Received METHOD frame for unregistered channel 1 on <SelectConnection OPEN transport=<pika.adapters.utils.io_services_utils._AsyncPlaintextTransport object at 0x76bb7dfea4d0> params=<ConnectionParameters host=localhost port=5672 virtual_host=/ ssl=False>>
2024-11-05 14:45:11 - INFO - pika.connection: Closing connection (200): 'Normal shutdown'
2024-11-05 14:45:11 - INFO - pika.adapters.utils.io_services_utils: Aborting transport connection: state=1; <socket.socket fd=17, family=AddressFamily.AF_INET, type=SocketKind.SOCK_STREAM, proto=6, laddr=('127.0.0.1', 54496), raddr=('127.0.0.1', 5672)>
2024-11-05 14:45:11 - INFO - pika.adapters.utils.io_services_utils: _AsyncTransportBase._initate_abort(): Initiating abrupt asynchronous transport shutdown: state=1; error=None; <socket.socket fd=17, family=AddressFamily.AF_INET, type=SocketKind.SOCK_STREAM, proto=6, laddr=('127.0.0.1', 54496), raddr=('127.0.0.1', 5672)>
2024-11-05 14:45:11 - INFO - pika.adapters.utils.io_services_utils: Deactivating transport: state=1; <socket.socket fd=17, family=AddressFamily.AF_INET, type=SocketKind.SOCK_STREAM, proto=6, laddr=('127.0.0.1', 54496), raddr=('127.0.0.1', 5672)>
2024-11-05 14:45:11 - INFO - pika.connection: AMQP stack terminated, failed to connect, or aborted: opened=True, error-arg=None; pending-error=ConnectionClosedByClient: (200) 'Normal shutdown'
2024-11-05 14:45:11 - INFO - pika.connection: Stack terminated due to ConnectionClosedByClient: (200) 'Normal shutdown'
2024-11-05 14:45:11 - INFO - pika.adapters.utils.io_services_utils: Closing transport socket and unlinking: state=3; <socket.socket fd=17, family=AddressFamily.AF_INET, type=SocketKind.SOCK_STREAM, proto=6, laddr=('127.0.0.1', 54496), raddr=('127.0.0.1', 5672)>
2024-11-05 14:45:11 - INFO - pika.adapters.blocking_connection: User-initiated close: result=BlockingConnection__OnClosedArgs(connection=<SelectConnection CLOSED transport=None params=<ConnectionParameters host=localhost port=5672 virtual_host=/ ssl=False>>, error=ConnectionClosedByClient: (200) 'Normal shutdown')
2024-11-05 14:45:11 - INFO - client: Connection to RabbitMQ closed.
2024-11-05 14:45:11 - ERROR - pika.adapters.utils.io_services_utils: _AsyncBaseTransport._produce() failed, aborting connection: error=IndexError('pop from an empty deque'); sock=<socket.socket [closed] fd=-1, family=AddressFamily.AF_INET, type=SocketKind.SOCK_STREAM, proto=6>; Caller's stack:
Traceback (most recent call last):
  File "/home/user/Desktop/GUI/venv/lib/python3.10/site-packages/pika/adapters/utils/io_services_utils.py", line 1103, in _on_socket_writable
    self._produce()
  File "/home/user/Desktop/GUI/venv/lib/python3.10/site-packages/pika/adapters/utils/io_services_utils.py", line 822, in _produce
    chunk = self._tx_buffers.popleft()
IndexError: pop from an empty deque
Traceback (most recent call last):
  File "/home/user/Desktop/GUI/venv/lib/python3.10/site-packages/pika/adapters/utils/io_services_utils.py", line 1103, in _on_socket_writable
    self._produce()
  File "/home/user/Desktop/GUI/venv/lib/python3.10/site-packages/pika/adapters/utils/io_services_utils.py", line 822, in _produce
    chunk = self._tx_buffers.popleft()
IndexError: pop from an empty deque
2024-11-05 14:45:11 - INFO - pika.adapters.utils.io_services_utils: _AsyncTransportBase._initate_abort(): Initiating abrupt asynchronous transport shutdown: state=4; error=IndexError('pop from an empty deque'); None
2024-11-05 14:45:11 - ERROR - pika.adapters.utils.io_services_utils: Wrapped func exited with exception. Caller's stack:
Traceback (most recent call last):
  File "/home/user/Desktop/GUI/venv/lib/python3.10/site-packages/pika/adapters/utils/io_services_utils.py", line 1103, in _on_socket_writable
    self._produce()
  File "/home/user/Desktop/GUI/venv/lib/python3.10/site-packages/pika/adapters/utils/io_services_utils.py", line 822, in _produce
    chunk = self._tx_buffers.popleft()
IndexError: pop from an empty deque

During handling of the above exception, another exception occurred:

Traceback (most recent call last):
  File "/home/user/Desktop/GUI/venv/lib/python3.10/site-packages/pika/diagnostic_utils.py", line 53, in log_exception_func_wrap
    return func(*args, **kwargs)
  File "/home/user/Desktop/GUI/venv/lib/python3.10/site-packages/pika/adapters/utils/io_services_utils.py", line 909, in _initiate_abort
    assert self._state != self._STATE_COMPLETED, (
AssertionError: ('_AsyncTransportBase._initate_abort() expected non-_STATE_COMPLETED', 4)
Traceback (most recent call last):
  File "/home/user/Desktop/GUI/venv/lib/python3.10/site-packages/pika/adapters/utils/io_services_utils.py", line 1103, in _on_socket_writable
    self._produce()
  File "/home/user/Desktop/GUI/venv/lib/python3.10/site-packages/pika/adapters/utils/io_services_utils.py", line 822, in _produce
    chunk = self._tx_buffers.popleft()
IndexError: pop from an empty deque

During handling of the above exception, another exception occurred:

Traceback (most recent call last):
  File "/home/user/Desktop/GUI/venv/lib/python3.10/site-packages/pika/diagnostic_utils.py", line 53, in log_exception_func_wrap
    return func(*args, **kwargs)
  File "/home/user/Desktop/GUI/venv/lib/python3.10/site-packages/pika/adapters/utils/io_services_utils.py", line 909, in _initiate_abort
    assert self._state != self._STATE_COMPLETED, (
AssertionError: ('_AsyncTransportBase._initate_abort() expected non-_STATE_COMPLETED', 4)
2024-11-05 14:45:11 - ERROR - pika.adapters.utils.io_services_utils: Wrapped func exited with exception. Caller's stack:
Traceback (most recent call last):
  File "/home/user/Desktop/GUI/venv/lib/python3.10/site-packages/pika/adapters/utils/io_services_utils.py", line 1103, in _on_socket_writable
    self._produce()
  File "/home/user/Desktop/GUI/venv/lib/python3.10/site-packages/pika/adapters/utils/io_services_utils.py", line 822, in _produce
    chunk = self._tx_buffers.popleft()
IndexError: pop from an empty deque

During handling of the above exception, another exception occurred:

Traceback (most recent call last):
  File "/home/user/Desktop/GUI/venv/lib/python3.10/site-packages/pika/diagnostic_utils.py", line 53, in log_exception_func_wrap
    return func(*args, **kwargs)
  File "/home/user/Desktop/GUI/venv/lib/python3.10/site-packages/pika/adapters/utils/io_services_utils.py", line 1114, in _on_socket_writable
    self._initiate_abort(error)
  File "/home/user/Desktop/GUI/venv/lib/python3.10/site-packages/pika/diagnostic_utils.py", line 53, in log_exception_func_wrap
    return func(*args, **kwargs)
  File "/home/user/Desktop/GUI/venv/lib/python3.10/site-packages/pika/adapters/utils/io_services_utils.py", line 909, in _initiate_abort
    assert self._state != self._STATE_COMPLETED, (
AssertionError: ('_AsyncTransportBase._initate_abort() expected non-_STATE_COMPLETED', 4)
Traceback (most recent call last):
  File "/home/user/Desktop/GUI/venv/lib/python3.10/site-packages/pika/adapters/utils/io_services_utils.py", line 1103, in _on_socket_writable
    self._produce()
  File "/home/user/Desktop/GUI/venv/lib/python3.10/site-packages/pika/adapters/utils/io_services_utils.py", line 822, in _produce
    chunk = self._tx_buffers.popleft()
IndexError: pop from an empty deque

During handling of the above exception, another exception occurred:

Traceback (most recent call last):
  File "/home/user/Desktop/GUI/venv/lib/python3.10/site-packages/pika/diagnostic_utils.py", line 53, in log_exception_func_wrap
    return func(*args, **kwargs)
  File "/home/user/Desktop/GUI/venv/lib/python3.10/site-packages/pika/adapters/utils/io_services_utils.py", line 1114, in _on_socket_writable
    self._initiate_abort(error)
  File "/home/user/Desktop/GUI/venv/lib/python3.10/site-packages/pika/diagnostic_utils.py", line 53, in log_exception_func_wrap
    return func(*args, **kwargs)
  File "/home/user/Desktop/GUI/venv/lib/python3.10/site-packages/pika/adapters/utils/io_services_utils.py", line 909, in _initiate_abort
    assert self._state != self._STATE_COMPLETED, (
AssertionError: ('_AsyncTransportBase._initate_abort() expected non-_STATE_COMPLETED', 4)
2024-11-05 14:45:11 - ERROR - client: Unexpected error: ('_AsyncTransportBase._initate_abort() expected non-_STATE_COMPLETED', 4)
2024-11-05 16:18:23 - INFO - pika.adapters.utils.connection_workflow: Pika version 1.3.2 connecting to ('127.0.0.1', 5672)
2024-11-05 16:18:23 - INFO - pika.adapters.utils.io_services_utils: Socket connected: <socket.socket fd=17, family=AddressFamily.AF_INET, type=SocketKind.SOCK_STREAM, proto=6, laddr=('127.0.0.1', 60500), raddr=('127.0.0.1', 5672)>
2024-11-05 16:18:23 - INFO - pika.adapters.utils.connection_workflow: Streaming transport linked up: (<pika.adapters.utils.io_services_utils._AsyncPlaintextTransport object at 0x7d60793e2410>, _StreamingProtocolShim: <SelectConnection PROTOCOL transport=<pika.adapters.utils.io_services_utils._AsyncPlaintextTransport object at 0x7d60793e2410> params=<ConnectionParameters host=localhost port=5672 virtual_host=/ ssl=False>>).
2024-11-05 16:18:23 - INFO - pika.adapters.utils.connection_workflow: AMQPConnector - reporting success: <SelectConnection OPEN transport=<pika.adapters.utils.io_services_utils._AsyncPlaintextTransport object at 0x7d60793e2410> params=<ConnectionParameters host=localhost port=5672 virtual_host=/ ssl=False>>
2024-11-05 16:18:23 - INFO - pika.adapters.utils.connection_workflow: AMQPConnectionWorkflow - reporting success: <SelectConnection OPEN transport=<pika.adapters.utils.io_services_utils._AsyncPlaintextTransport object at 0x7d60793e2410> params=<ConnectionParameters host=localhost port=5672 virtual_host=/ ssl=False>>
2024-11-05 16:18:23 - INFO - pika.adapters.blocking_connection: Connection workflow succeeded: <SelectConnection OPEN transport=<pika.adapters.utils.io_services_utils._AsyncPlaintextTransport object at 0x7d60793e2410> params=<ConnectionParameters host=localhost port=5672 virtual_host=/ ssl=False>>
2024-11-05 16:18:23 - INFO - pika.adapters.blocking_connection: Created channel=1
2024-11-05 16:18:23 - INFO - client: Connected to RabbitMQ and listening on queue: amq.gen-cReVZo7vhkBy4Mf_j5OvOA
2024-11-05 16:18:23 - INFO - client: Sent heartbeat message 'PING' to server.
2024-11-05 16:18:23 - INFO - client: Received response: PONG for request ID: 678773ad-c122-471b-bd21-e0b8c15bd946
2024-11-05 16:18:23 - INFO - client: Received heartbeat response PONG from server.
2024-11-05 16:18:32 - INFO - pika.adapters.blocking_connection: Closing connection (200): Normal shutdown
2024-11-05 16:18:32 - ERROR - pika.adapters.utils.io_services_utils: _AsyncBaseTransport._produce() failed, aborting connection: error=IndexError('pop from an empty deque'); sock=<socket.socket fd=17, family=AddressFamily.AF_INET, type=SocketKind.SOCK_STREAM, proto=6, laddr=('127.0.0.1', 60500), raddr=('127.0.0.1', 5672)>; Caller's stack:
Traceback (most recent call last):
  File "/home/user/Desktop/GUI/venv/lib/python3.10/site-packages/pika/adapters/utils/io_services_utils.py", line 1103, in _on_socket_writable
    self._produce()
  File "/home/user/Desktop/GUI/venv/lib/python3.10/site-packages/pika/adapters/utils/io_services_utils.py", line 822, in _produce
    chunk = self._tx_buffers.popleft()
IndexError: pop from an empty deque
Traceback (most recent call last):
  File "/home/user/Desktop/GUI/venv/lib/python3.10/site-packages/pika/adapters/utils/io_services_utils.py", line 1103, in _on_socket_writable
    self._produce()
  File "/home/user/Desktop/GUI/venv/lib/python3.10/site-packages/pika/adapters/utils/io_services_utils.py", line 822, in _produce
    chunk = self._tx_buffers.popleft()
IndexError: pop from an empty deque
2024-11-05 16:18:32 - ERROR - pika.channel: Unexpected frame: <METHOD(['channel_number=1', 'frame_type=1', "method=<Basic.CancelOk(['consumer_tag=ctag1.cfc09279a3b2416988e3c5ab88d16202'])>"])>
2024-11-05 16:18:32 - INFO - pika.adapters.utils.io_services_utils: _AsyncTransportBase._initate_abort(): Initiating abrupt asynchronous transport shutdown: state=1; error=IndexError('pop from an empty deque'); <socket.socket fd=17, family=AddressFamily.AF_INET, type=SocketKind.SOCK_STREAM, proto=6, laddr=('127.0.0.1', 60500), raddr=('127.0.0.1', 5672)>
2024-11-05 16:18:32 - INFO - pika.channel: Closing channel (200): 'Normal shutdown' on <Channel number=1 OPEN conn=<SelectConnection OPEN transport=<pika.adapters.utils.io_services_utils._AsyncPlaintextTransport object at 0x7d60793e2410> params=<ConnectionParameters host=localhost port=5672 virtual_host=/ ssl=False>>>
2024-11-05 16:18:32 - INFO - pika.adapters.utils.io_services_utils: Deactivating transport: state=1; <socket.socket fd=17, family=AddressFamily.AF_INET, type=SocketKind.SOCK_STREAM, proto=6, laddr=('127.0.0.1', 60500), raddr=('127.0.0.1', 5672)>
2024-11-05 16:18:32 - ERROR - pika.adapters.base_connection: connection_lost: StreamLostError: ("Stream connection lost: IndexError('pop from an empty deque')",)
2024-11-05 16:18:32 - INFO - pika.connection: AMQP stack terminated, failed to connect, or aborted: opened=True, error-arg=StreamLostError: ("Stream connection lost: IndexError('pop from an empty deque')",); pending-error=None
2024-11-05 16:18:32 - INFO - pika.connection: Stack terminated due to StreamLostError: ("Stream connection lost: IndexError('pop from an empty deque')",)
2024-11-05 16:18:32 - INFO - pika.adapters.utils.io_services_utils: Closing transport socket and unlinking: state=2; <socket.socket fd=17, family=AddressFamily.AF_INET, type=SocketKind.SOCK_STREAM, proto=6, laddr=('127.0.0.1', 60500), raddr=('127.0.0.1', 5672)>
2024-11-05 16:18:32 - ERROR - pika.adapters.utils.io_services_utils: _AsyncBaseTransport._produce() failed, aborting connection: error=IndexError('pop from an empty deque'); sock=<socket.socket fd=17, family=AddressFamily.AF_INET, type=SocketKind.SOCK_STREAM, proto=6, laddr=('127.0.0.1', 60500), raddr=('127.0.0.1', 5672)>; Caller's stack:
Traceback (most recent call last):
  File "/home/user/Desktop/GUI/venv/lib/python3.10/site-packages/pika/adapters/utils/io_services_utils.py", line 1103, in _on_socket_writable
    self._produce()
  File "/home/user/Desktop/GUI/venv/lib/python3.10/site-packages/pika/adapters/utils/io_services_utils.py", line 822, in _produce
    chunk = self._tx_buffers.popleft()
IndexError: pop from an empty deque
Traceback (most recent call last):
  File "/home/user/Desktop/GUI/venv/lib/python3.10/site-packages/pika/adapters/utils/io_services_utils.py", line 1103, in _on_socket_writable
    self._produce()
  File "/home/user/Desktop/GUI/venv/lib/python3.10/site-packages/pika/adapters/utils/io_services_utils.py", line 822, in _produce
    chunk = self._tx_buffers.popleft()
IndexError: pop from an empty deque
2024-11-05 16:18:32 - INFO - pika.adapters.utils.io_services_utils: _AsyncTransportBase._initate_abort(): Initiating abrupt asynchronous transport shutdown: state=2; error=IndexError('pop from an empty deque'); <socket.socket [closed] fd=-1, family=AddressFamily.AF_INET, type=SocketKind.SOCK_STREAM, proto=6>
2024-11-05 16:18:32 - ERROR - pika.adapters.blocking_connection: Unexpected connection close detected: StreamLostError: ("Stream connection lost: IndexError('pop from an empty deque')",)
2024-11-05 16:18:32 - ERROR - client: AMQP Error: Stream connection lost: IndexError('pop from an empty deque')
2024-11-05 16:18:32 - ERROR - pika.adapters.utils.io_services_utils: Wrapped func exited with exception. Caller's stack:
Traceback (most recent call last):
  File "/home/user/Desktop/GUI/venv/lib/python3.10/site-packages/pika/adapters/utils/io_services_utils.py", line 1103, in _on_socket_writable
    self._produce()
  File "/home/user/Desktop/GUI/venv/lib/python3.10/site-packages/pika/adapters/utils/io_services_utils.py", line 822, in _produce
    chunk = self._tx_buffers.popleft()
IndexError: pop from an empty deque

During handling of the above exception, another exception occurred:

Traceback (most recent call last):
  File "/home/user/Desktop/GUI/venv/lib/python3.10/site-packages/pika/diagnostic_utils.py", line 53, in log_exception_func_wrap
    return func(*args, **kwargs)
  File "/home/user/Desktop/GUI/venv/lib/python3.10/site-packages/pika/adapters/utils/io_services_utils.py", line 909, in _initiate_abort
    assert self._state != self._STATE_COMPLETED, (
AssertionError: ('_AsyncTransportBase._initate_abort() expected non-_STATE_COMPLETED', 4)
Traceback (most recent call last):
  File "/home/user/Desktop/GUI/venv/lib/python3.10/site-packages/pika/adapters/utils/io_services_utils.py", line 1103, in _on_socket_writable
    self._produce()
  File "/home/user/Desktop/GUI/venv/lib/python3.10/site-packages/pika/adapters/utils/io_services_utils.py", line 822, in _produce
    chunk = self._tx_buffers.popleft()
IndexError: pop from an empty deque

During handling of the above exception, another exception occurred:

Traceback (most recent call last):
  File "/home/user/Desktop/GUI/venv/lib/python3.10/site-packages/pika/diagnostic_utils.py", line 53, in log_exception_func_wrap
    return func(*args, **kwargs)
  File "/home/user/Desktop/GUI/venv/lib/python3.10/site-packages/pika/adapters/utils/io_services_utils.py", line 909, in _initiate_abort
    assert self._state != self._STATE_COMPLETED, (
AssertionError: ('_AsyncTransportBase._initate_abort() expected non-_STATE_COMPLETED', 4)
2024-11-05 16:18:32 - ERROR - pika.adapters.utils.io_services_utils: Wrapped func exited with exception. Caller's stack:
Traceback (most recent call last):
  File "/home/user/Desktop/GUI/venv/lib/python3.10/site-packages/pika/adapters/utils/io_services_utils.py", line 1103, in _on_socket_writable
    self._produce()
  File "/home/user/Desktop/GUI/venv/lib/python3.10/site-packages/pika/adapters/utils/io_services_utils.py", line 822, in _produce
    chunk = self._tx_buffers.popleft()
IndexError: pop from an empty deque

During handling of the above exception, another exception occurred:

Traceback (most recent call last):
  File "/home/user/Desktop/GUI/venv/lib/python3.10/site-packages/pika/diagnostic_utils.py", line 53, in log_exception_func_wrap
    return func(*args, **kwargs)
  File "/home/user/Desktop/GUI/venv/lib/python3.10/site-packages/pika/adapters/utils/io_services_utils.py", line 1114, in _on_socket_writable
    self._initiate_abort(error)
  File "/home/user/Desktop/GUI/venv/lib/python3.10/site-packages/pika/diagnostic_utils.py", line 53, in log_exception_func_wrap
    return func(*args, **kwargs)
  File "/home/user/Desktop/GUI/venv/lib/python3.10/site-packages/pika/adapters/utils/io_services_utils.py", line 909, in _initiate_abort
    assert self._state != self._STATE_COMPLETED, (
AssertionError: ('_AsyncTransportBase._initate_abort() expected non-_STATE_COMPLETED', 4)
Traceback (most recent call last):
  File "/home/user/Desktop/GUI/venv/lib/python3.10/site-packages/pika/adapters/utils/io_services_utils.py", line 1103, in _on_socket_writable
    self._produce()
  File "/home/user/Desktop/GUI/venv/lib/python3.10/site-packages/pika/adapters/utils/io_services_utils.py", line 822, in _produce
    chunk = self._tx_buffers.popleft()
IndexError: pop from an empty deque

During handling of the above exception, another exception occurred:

Traceback (most recent call last):
  File "/home/user/Desktop/GUI/venv/lib/python3.10/site-packages/pika/diagnostic_utils.py", line 53, in log_exception_func_wrap
    return func(*args, **kwargs)
  File "/home/user/Desktop/GUI/venv/lib/python3.10/site-packages/pika/adapters/utils/io_services_utils.py", line 1114, in _on_socket_writable
    self._initiate_abort(error)
  File "/home/user/Desktop/GUI/venv/lib/python3.10/site-packages/pika/diagnostic_utils.py", line 53, in log_exception_func_wrap
    return func(*args, **kwargs)
  File "/home/user/Desktop/GUI/venv/lib/python3.10/site-packages/pika/adapters/utils/io_services_utils.py", line 909, in _initiate_abort
    assert self._state != self._STATE_COMPLETED, (
AssertionError: ('_AsyncTransportBase._initate_abort() expected non-_STATE_COMPLETED', 4)
2024-11-05 16:18:32 - ERROR - client: Error closing connection: ('_AsyncTransportBase._initate_abort() expected non-_STATE_COMPLETED', 4)
2024-11-05 16:19:57 - INFO - pika.adapters.utils.connection_workflow: Pika version 1.3.2 connecting to ('127.0.0.1', 5672)
2024-11-05 16:19:57 - INFO - pika.adapters.utils.io_services_utils: Socket connected: <socket.socket fd=17, family=AddressFamily.AF_INET, type=SocketKind.SOCK_STREAM, proto=6, laddr=('127.0.0.1', 34882), raddr=('127.0.0.1', 5672)>
2024-11-05 16:19:57 - INFO - pika.adapters.utils.connection_workflow: Streaming transport linked up: (<pika.adapters.utils.io_services_utils._AsyncPlaintextTransport object at 0x7c24115ea4a0>, _StreamingProtocolShim: <SelectConnection PROTOCOL transport=<pika.adapters.utils.io_services_utils._AsyncPlaintextTransport object at 0x7c24115ea4a0> params=<ConnectionParameters host=localhost port=5672 virtual_host=/ ssl=False>>).
2024-11-05 16:19:57 - INFO - pika.adapters.utils.connection_workflow: AMQPConnector - reporting success: <SelectConnection OPEN transport=<pika.adapters.utils.io_services_utils._AsyncPlaintextTransport object at 0x7c24115ea4a0> params=<ConnectionParameters host=localhost port=5672 virtual_host=/ ssl=False>>
2024-11-05 16:19:57 - INFO - pika.adapters.utils.connection_workflow: AMQPConnectionWorkflow - reporting success: <SelectConnection OPEN transport=<pika.adapters.utils.io_services_utils._AsyncPlaintextTransport object at 0x7c24115ea4a0> params=<ConnectionParameters host=localhost port=5672 virtual_host=/ ssl=False>>
2024-11-05 16:19:57 - INFO - pika.adapters.blocking_connection: Connection workflow succeeded: <SelectConnection OPEN transport=<pika.adapters.utils.io_services_utils._AsyncPlaintextTransport object at 0x7c24115ea4a0> params=<ConnectionParameters host=localhost port=5672 virtual_host=/ ssl=False>>
2024-11-05 16:19:57 - INFO - pika.adapters.blocking_connection: Created channel=1
2024-11-05 16:19:57 - INFO - client: Connected to RabbitMQ and listening on queue: amq.gen-OVYjiipYS_NdaTcoZ-uM-w
2024-11-05 16:19:57 - INFO - client: Sent heartbeat message 'PING' to server.
2024-11-05 16:20:00 - INFO - client: Received response: PONG for request ID: ee146cec-87a1-47ad-bb80-0357bb925b9d
2024-11-05 16:20:00 - INFO - client: Received heartbeat response PONG from server.
2024-11-05 16:20:04 - INFO - pika.adapters.blocking_connection: Closing connection (200): Normal shutdown
2024-11-05 16:20:04 - ERROR - pika.adapters.utils.io_services_utils: _AsyncBaseTransport._produce() failed, aborting connection: error=IndexError('pop from an empty deque'); sock=<socket.socket fd=17, family=AddressFamily.AF_INET, type=SocketKind.SOCK_STREAM, proto=6, laddr=('127.0.0.1', 34882), raddr=('127.0.0.1', 5672)>; Caller's stack:
Traceback (most recent call last):
  File "/home/user/Desktop/GUI/venv/lib/python3.10/site-packages/pika/adapters/utils/io_services_utils.py", line 1103, in _on_socket_writable
    self._produce()
  File "/home/user/Desktop/GUI/venv/lib/python3.10/site-packages/pika/adapters/utils/io_services_utils.py", line 822, in _produce
    chunk = self._tx_buffers.popleft()
IndexError: pop from an empty deque
Traceback (most recent call last):
  File "/home/user/Desktop/GUI/venv/lib/python3.10/site-packages/pika/adapters/utils/io_services_utils.py", line 1103, in _on_socket_writable
    self._produce()
  File "/home/user/Desktop/GUI/venv/lib/python3.10/site-packages/pika/adapters/utils/io_services_utils.py", line 822, in _produce
    chunk = self._tx_buffers.popleft()
IndexError: pop from an empty deque
2024-11-05 16:20:04 - INFO - pika.adapters.utils.io_services_utils: _AsyncTransportBase._initate_abort(): Initiating abrupt asynchronous transport shutdown: state=1; error=IndexError('pop from an empty deque'); <socket.socket fd=17, family=AddressFamily.AF_INET, type=SocketKind.SOCK_STREAM, proto=6, laddr=('127.0.0.1', 34882), raddr=('127.0.0.1', 5672)>
2024-11-05 16:20:04 - INFO - pika.adapters.utils.io_services_utils: Deactivating transport: state=1; <socket.socket fd=17, family=AddressFamily.AF_INET, type=SocketKind.SOCK_STREAM, proto=6, laddr=('127.0.0.1', 34882), raddr=('127.0.0.1', 5672)>
2024-11-05 16:20:04 - ERROR - pika.adapters.base_connection: connection_lost: StreamLostError: ("Stream connection lost: IndexError('pop from an empty deque')",)
2024-11-05 16:20:04 - INFO - pika.connection: AMQP stack terminated, failed to connect, or aborted: opened=True, error-arg=StreamLostError: ("Stream connection lost: IndexError('pop from an empty deque')",); pending-error=None
2024-11-05 16:20:04 - INFO - pika.connection: Stack terminated due to StreamLostError: ("Stream connection lost: IndexError('pop from an empty deque')",)
2024-11-05 16:20:04 - INFO - pika.adapters.utils.io_services_utils: Closing transport socket and unlinking: state=2; <socket.socket fd=17, family=AddressFamily.AF_INET, type=SocketKind.SOCK_STREAM, proto=6, laddr=('127.0.0.1', 34882), raddr=('127.0.0.1', 5672)>
2024-11-05 16:20:04 - ERROR - pika.adapters.blocking_connection: Unexpected connection close detected: StreamLostError: ("Stream connection lost: IndexError('pop from an empty deque')",)
2024-11-05 16:20:04 - ERROR - client: AMQP Error: Stream connection lost: IndexError('pop from an empty deque')
2024-11-05 16:20:04 - ERROR - client: Error closing connection: 'NoneType' object has no attribute 'clear'
>>>>>>> d3c6af0a7c94cb7e4a2881f3789a5023355304dc
2024-11-05 22:35:37 - INFO - pika.adapters.utils.connection_workflow: Pika version 1.3.2 connecting to ('::1', 5672, 0, 0)
2024-11-05 22:35:39 - ERROR - pika.adapters.utils.io_services_utils: Socket failed to connect: <socket.socket fd=1400, family=23, type=1, proto=6, laddr=('::', 60931, 0, 0)>; error=10061 (Unknown error)
2024-11-05 22:35:39 - ERROR - pika.adapters.utils.connection_workflow: TCP Connection attempt failed: ConnectionRefusedError(10061, 'Unknown error'); dest=(<AddressFamily.AF_INET6: 23>, <SocketKind.SOCK_STREAM: 1>, 6, '', ('::1', 5672, 0, 0))
2024-11-05 22:35:39 - ERROR - pika.adapters.utils.connection_workflow: AMQPConnector - reporting failure: AMQPConnectorSocketConnectError: ConnectionRefusedError(10061, 'Unknown error')
2024-11-05 22:35:39 - INFO - pika.adapters.utils.connection_workflow: Pika version 1.3.2 connecting to ('127.0.0.1', 5672)
2024-11-05 22:35:41 - ERROR - pika.adapters.utils.io_services_utils: Socket failed to connect: <socket.socket fd=1400, family=2, type=1, proto=6, laddr=('0.0.0.0', 60935)>; error=10061 (Unknown error)
2024-11-05 22:35:41 - ERROR - pika.adapters.utils.connection_workflow: TCP Connection attempt failed: ConnectionRefusedError(10061, 'Unknown error'); dest=(<AddressFamily.AF_INET: 2>, <SocketKind.SOCK_STREAM: 1>, 6, '', ('127.0.0.1', 5672))
2024-11-05 22:35:41 - ERROR - pika.adapters.utils.connection_workflow: AMQPConnector - reporting failure: AMQPConnectorSocketConnectError: ConnectionRefusedError(10061, 'Unknown error')
2024-11-05 22:35:41 - ERROR - pika.adapters.utils.connection_workflow: AMQP connection workflow failed: AMQPConnectionWorkflowFailed: 2 exceptions in all; last exception - AMQPConnectorSocketConnectError: ConnectionRefusedError(10061, 'Unknown error'); first exception - AMQPConnectorSocketConnectError: ConnectionRefusedError(10061, 'Unknown error').
2024-11-05 22:35:41 - ERROR - pika.adapters.utils.connection_workflow: AMQPConnectionWorkflow - reporting failure: AMQPConnectionWorkflowFailed: 2 exceptions in all; last exception - AMQPConnectorSocketConnectError: ConnectionRefusedError(10061, 'Unknown error'); first exception - AMQPConnectorSocketConnectError: ConnectionRefusedError(10061, 'Unknown error')
2024-11-05 22:35:41 - ERROR - pika.adapters.blocking_connection: Connection workflow failed: AMQPConnectionWorkflowFailed: 2 exceptions in all; last exception - AMQPConnectorSocketConnectError: ConnectionRefusedError(10061, 'Unknown error'); first exception - AMQPConnectorSocketConnectError: ConnectionRefusedError(10061, 'Unknown error')
2024-11-05 22:35:41 - ERROR - pika.adapters.blocking_connection: Error in _create_connection().
Traceback (most recent call last):
  File "Z:\conda\envs\pyqt-env\Lib\site-packages\pika\adapters\blocking_connection.py", line 451, in _create_connection
    raise self._reap_last_connection_workflow_error(error)
pika.exceptions.AMQPConnectionError
2024-11-05 22:35:41 - ERROR - client: Failed to connect to RabbitMQ: 
2024-11-05 22:37:27 - INFO - pika.adapters.utils.connection_workflow: Pika version 1.3.2 connecting to ('::1', 5672, 0, 0)
2024-11-05 22:37:29 - ERROR - pika.adapters.utils.io_services_utils: Socket failed to connect: <socket.socket fd=992, family=23, type=1, proto=6, laddr=('::', 61050, 0, 0)>; error=10061 (Unknown error)
2024-11-05 22:37:29 - ERROR - pika.adapters.utils.connection_workflow: TCP Connection attempt failed: ConnectionRefusedError(10061, 'Unknown error'); dest=(<AddressFamily.AF_INET6: 23>, <SocketKind.SOCK_STREAM: 1>, 6, '', ('::1', 5672, 0, 0))
2024-11-05 22:37:29 - ERROR - pika.adapters.utils.connection_workflow: AMQPConnector - reporting failure: AMQPConnectorSocketConnectError: ConnectionRefusedError(10061, 'Unknown error')
2024-11-05 22:37:29 - INFO - pika.adapters.utils.connection_workflow: Pika version 1.3.2 connecting to ('127.0.0.1', 5672)
2024-11-05 22:37:31 - ERROR - pika.adapters.utils.io_services_utils: Socket failed to connect: <socket.socket fd=992, family=2, type=1, proto=6, laddr=('0.0.0.0', 61054)>; error=10061 (Unknown error)
2024-11-05 22:37:31 - ERROR - pika.adapters.utils.connection_workflow: TCP Connection attempt failed: ConnectionRefusedError(10061, 'Unknown error'); dest=(<AddressFamily.AF_INET: 2>, <SocketKind.SOCK_STREAM: 1>, 6, '', ('127.0.0.1', 5672))
2024-11-05 22:37:31 - ERROR - pika.adapters.utils.connection_workflow: AMQPConnector - reporting failure: AMQPConnectorSocketConnectError: ConnectionRefusedError(10061, 'Unknown error')
2024-11-05 22:37:31 - ERROR - pika.adapters.utils.connection_workflow: AMQP connection workflow failed: AMQPConnectionWorkflowFailed: 2 exceptions in all; last exception - AMQPConnectorSocketConnectError: ConnectionRefusedError(10061, 'Unknown error'); first exception - AMQPConnectorSocketConnectError: ConnectionRefusedError(10061, 'Unknown error').
2024-11-05 22:37:31 - ERROR - pika.adapters.utils.connection_workflow: AMQPConnectionWorkflow - reporting failure: AMQPConnectionWorkflowFailed: 2 exceptions in all; last exception - AMQPConnectorSocketConnectError: ConnectionRefusedError(10061, 'Unknown error'); first exception - AMQPConnectorSocketConnectError: ConnectionRefusedError(10061, 'Unknown error')
2024-11-05 22:37:31 - ERROR - pika.adapters.blocking_connection: Connection workflow failed: AMQPConnectionWorkflowFailed: 2 exceptions in all; last exception - AMQPConnectorSocketConnectError: ConnectionRefusedError(10061, 'Unknown error'); first exception - AMQPConnectorSocketConnectError: ConnectionRefusedError(10061, 'Unknown error')
2024-11-05 22:37:31 - ERROR - pika.adapters.blocking_connection: Error in _create_connection().
Traceback (most recent call last):
  File "Z:\conda\envs\pyqt-env\Lib\site-packages\pika\adapters\blocking_connection.py", line 451, in _create_connection
    raise self._reap_last_connection_workflow_error(error)
pika.exceptions.AMQPConnectionError
2024-11-05 22:37:31 - ERROR - client: Failed to connect to RabbitMQ: 
